<?xml version="1.0"?>
<robot name="harsh_bot">

  <!-- Main body link -->
  <link name="base_link">
    <visual>
      <geometry>
        <box size="0.2 0.2 0.1"/> <!-- 200mm x 200mm x 100mm -->
      </geometry>
      <material name="grey">
        <color rgba="0.7 0.7 0.7 1"/>
      </material>
    </visual>
    <collision>
      <geometry>
        <box size="0.2 0.2 0.1"/>
      </geometry>
    </collision>
    <inertial>
      <mass value="1.0"/>
      <origin xyz="0 0 0"/>
      <inertia ixx="0.01" ixy="0.0" ixz="0.0" iyy="0.01" iyz="0.0" izz="0.01"/>
    </inertial>
  </link>

  <!-- Right Wheel -->
  <link name="right_wheel">
    <visual>
      <geometry>
        <cylinder radius="0.06" length="0.065"/> <!-- 120mm diameter, 65mm wide -->
      </geometry>
      <material name="black">
        <color rgba="0 0 0 1"/>
      </material>
    </visual>
    <collision>
      <geometry>
        <cylinder radius="0.06" length="0.065"/>
      </geometry>
    </collision>
    <inertial>
      <mass value="0.2"/>
      <origin xyz="0 0 0"/>
      <inertia ixx="0.001" ixy="0.0" ixz="0.0" iyy="0.001" iyz="0.0" izz="0.001"/>
    </inertial>
  </link>

  <!-- Left Wheel -->
  <link name="left_wheel">
    <visual>
      <geometry>
        <cylinder radius="0.06" length="0.065"/>
      </geometry>
      <material name="black">
        <color rgba="0 0 0 1"/>
      </material>
    </visual>
    <collision>
      <geometry>
        <cylinder radius="0.06" length="0.065"/>
      </geometry>
    </collision>
    <inertial>
      <mass value="0.2"/>
      <origin xyz="0 0 0"/>
      <inertia ixx="0.001" ixy="0.0" ixz="0.0" iyy="0.001" iyz="0.0" izz="0.001"/>
    </inertial>
  </link>

  <!-- Base support -->
  <link name="sphere_ball">
    <visual>
      <geometry>
        <sphere radius="0.021"/> <!-- 21mm diameter -->
      </geometry>
      <material name="red">
        <color rgba="1 0.0 0.0 1"/>
      </material>
    </visual>
    <collision>
      <geometry>
        <sphere radius="0.021"/>
      </geometry>
    </collision>
    <inertial>
      <mass value="0.1"/>
      <origin xyz="0 0 0"/>
      <inertia ixx="0.0001" ixy="0.0" ixz="0.0" iyy="0.0001" iyz="0.0" izz="0.0001"/>
    </inertial>
  </link>

  <!-- Joints -->
  <joint name="right_wheel_joint" type="continuous">
    <parent link="base_link"/>
    <child link="right_wheel"/>
    <origin xyz="-0.03 0.1 -0.025" rpy="1.56 0 0"/> <!-- Adjusted for proper wheel placement -->
    <axis xyz="0 1 0"/>
  </joint>

  <joint name="left_wheel_joint" type="continuous">
    <parent link="base_link"/>
    <child link="left_wheel"/>
    <origin xyz="-0.03 -0.1 -0.025" rpy="1.56 0 0"/> <!-- Adjusted for proper wheel placement -->
    <axis xyz="0 1 0"/>
  </joint>

  <joint name="base_support_joint" type="fixed">
    <parent link="base_link"/>
    <child link="sphere_ball"/>
    <origin xyz="0.06 0.0 -0.055" rpy="0 0 0"/> <!-- Base support attached to bottom center -->
  </joint>

  <!-- Transmissions -->
  <transmission name="right_wheel_trans">
    <type>transmission_interface/SimpleTransmission</type>
    <joint name="right_wheel_joint">
      <hardwareInterface>hardware_interface/EffortJointInterface</hardwareInterface>
    </joint>
    <actuator name="right_wheel_motor">
      <hardwareInterface>hardware_interface/EffortJointInterface</hardwareInterface>
      <mechanicalReduction>1</mechanicalReduction>
    </actuator>
  </transmission>

  <transmission name="left_wheel_trans">
    <type>transmission_interface/SimpleTransmission</type>
    <joint name="left_wheel_joint">
      <hardwareInterface>hardware_interface/EffortJointInterface</hardwareInterface>
    </joint>
    <actuator name="left_wheel_motor">
      <hardwareInterface>hardware_interface/EffortJointInterface</hardwareInterface>
      <mechanicalReduction>1</mechanicalReduction>
    </actuator>
  </transmission>

  <!-- Gazebo Friction and Damping -->
  <gazebo reference="right_wheel">
    <mu1>0.9</mu1>
    <mu2>0.9</mu2>
    <damping>0.01</damping>
  </gazebo>

  <gazebo reference="left_wheel">
    <mu1>0.9</mu1>
    <mu2>0.9</mu2>
    <damping>0.01</damping>
  </gazebo>

  <!-- Gazebo Plugin for ROS control -->
  <gazebo>
    <plugin name="gazebo_ros_control" filename="libgazebo_ros_control.so">
      <robotNamespace>/harsh_bot</robotNamespace>
    </plugin>
  </gazebo>

</robot>

